Workbook

Sheet Tracker
A1: NeetCode 150 — Personal Progress Tracker
A2: Fill in columns G through Q as you solve each problem. Row 4 is a filled-in EXAMPLE — overwrite it with your own data. See the 'Method & Timeline' tab for NeetCode's study method and a legend.
A3: # | B3: Topic | C3: Problem | D3: Difficulty | E3: LeetCode Link | F3: NeetCode Video | G3: Date Attempted | H3: Time Taken (min) | I3: Solved Independently? (Y/N) | J3: Watched Video? (Y/N) | K3: Pattern / Approach | L3: My Notes | M3: Needs Revisit? (Y/N) | N3: Revisit Date | O3: Revisit — Solved From Scratch? (Y/N) | P3: Confidence (1-5) | Q3: Status
A4: 1 | B4: Arrays & Hashing | C4: Contains Duplicate | D4: Easy | E4: Open | F4: Watch | G4: 2026-08-10 | H4: 14 | I4: Y | J4: N | K4: Hash Set — track seen numbers, O(n) time / O(n) space | L4: used set datatype of python remembered set lookup is O(1). Easy warm-up problem. | M4: N | P4: 5 | Q4: Solved Independently
A5: 2 | B5: Arrays & Hashing | C5: Valid Anagram | D5: Easy | E5: Open | F5: Watch
A6: 3 | B6: Arrays & Hashing | C6: Two Sum | D6: Easy | E6: Open | F6: Watch | G6: 46241 | H6: 10 | I6: N | J6: Y | M6: Y | P6: 2
A7: 4 | B7: Arrays & Hashing | C7: Group Anagrams | D7: Medium | E7: Open | F7: Watch
A8: 5 | B8: Arrays & Hashing | C8: Top K Frequent Elements | D8: Medium | E8: Open | F8: Watch
A9: 6 | B9: Arrays & Hashing | C9: Encode and Decode Strings | D9: Medium | E9: Open | F9: Watch
A10: 7 | B10: Arrays & Hashing | C10: Product of Array Except Self | D10: Medium | E10: Open | F10: Watch
A11: 8 | B11: Arrays & Hashing | C11: Valid Sudoku | D11: Medium | E11: Open | F11: Watch
A12: 9 | B12: Arrays & Hashing | C12: Longest Consecutive Sequence | D12: Medium | E12: Open | F12: Watch
A13: 10 | B13: Two Pointers | C13: Valid Palindrome | D13: Easy | E13: Open | F13: Watch
A14: 11 | B14: Two Pointers | C14: Two Sum II Input Array Is Sorted | D14: Medium | E14: Open | F14: Watch
A15: 12 | B15: Two Pointers | C15: 3Sum | D15: Medium | E15: Open | F15: Watch
A16: 13 | B16: Two Pointers | C16: Container With Most Water | D16: Medium | E16: Open | F16: Watch
A17: 14 | B17: Two Pointers | C17: Trapping Rain Water | D17: Hard | E17: Open | F17: Watch
A18: 15 | B18: Sliding Window | C18: Best Time to Buy And Sell Stock | D18: Easy | E18: Open | F18: Watch
... A23: 20 | B23: Sliding Window | C23: Sliding Window Maximum | D23: Hard | E23: Open | F23: Watch
A24: 21 | B24: Stack | C24: Valid Parentheses | D24: Easy | E24: Open | F24: Watch | G24: 46211 | H24: 30 | I24: N | J24: Y | M24: Y | P24: 2
A25: 22 | B25: Stack | C25: Min Stack | D25: Medium | E25: Open | F25: Watch
A26: 23 | B26: Stack | C26: Evaluate Reverse Polish Notation | D26: Medium | E26: Open | F26: Watch
A27: 24 | B27: Stack | C27: Daily Temperatures | D27: Medium | E27: Open | F27: Watch
A28: 25 | B28: Stack | C28: Car Fleet | D28: Medium | E28: Open | F28: Watch
A29: 26 | B29: Stack | C29: Largest Rectangle In Histogram | D29: Hard | E29: Open | F29: Watch
A30: 27 | B30: Binary Search | C30: Binary Search | D30: Easy | E30: Open | F30: Watch | G30: 46241 | H30: 20 | I30: N | J30: Y | M30: Y | P30: 2
A31: 28 | B31: Binary Search | C31: Search a 2D Matrix | D31: Medium | E31: Open | F31: Watch
A32: 29 | B32: Binary Search | C32: Koko Eating Bananas | D32: Medium | E32: Open | F32: Watch
A33: 30 | B33: Binary Search | C33: Find Minimum In Rotated Sorted Array | D33: Medium | E33: Open | F33: Watch
A34: 31 | B34: Binary Search | C34: Search In Rotated Sorted Array | D34: Medium | E34: Open | F34: Watch
A35: 32 | B35: Binary Search | C35: Time Based Key Value Store | D35: Medium | E35: Open | F35: Watch
A36: 33 | B36: Binary Search | C36: Median of Two Sorted Arrays | D36: Hard | E36: Open | F36: Watch
A37: 34 | B37: Linked List | C37: Reverse Linked List | D37: Easy | E37: Open | F37: Watch | G37: 46241 | H37: 30 | I37: N | J37: Y | M37: Y | P37: 2
A38: 35 | B38: Linked List | C38: Merge Two Sorted Lists | D38: Easy | E38: Open | F38: Watch | G38: 46241 | H38: 30 | I38: N | J38: Y | M38: Y | P38: 2
A39: 36 | B39: Linked List | C39: Linked List Cycle | D39: Easy | E39: Open | F39: Watch | G39: 46241 | H39: 30 | I39: N | J39: Y | M39: Y | P39: 2
A40: 37 | B40: Linked List | C40: Reorder List | D40: Medium | E40: Open | F40: Watch
A41: 38 | B41: Linked List | C41: Remove Nth Node From End of List | D41: Medium | E41: Open | F41: Watch
A42: 39 | B42: Linked List | C42: Copy List With Random Pointer | D42: Medium | E42: Open | F42: Watch
A43: 40 | B43: Linked List | C43: Add Two Numbers | D43: Medium | E43: Open | F43: Watch
A44: 41 | B44: Linked List | C44: Find The Duplicate Number | D44: Medium | E44: Open | F44: Watch
...

Sheet Dashboard
A1: NeetCode 150 — Progress Dashboard
A2: All numbers below are live formulas pulling from the Tracker tab — update Tracker and this page updates itself.
A4: Topic | B4: Total Problems | C4: Solved (Independent/Mastered) | D4: % Complete | E4: Needs Revisit | F4: Avg Confidence
A5: Arrays & Hashing | B5: =COUNTIF(Tracker!$B$4:$B$153,A5) -> 9 | C5: 1 | D5: =IFERROR(C5/B5,0) -> 0.11111111 | E5: =COUNTIFS(Tracker!$B$4:$B$153,A5,Tracker!$M$4:$M$153,"Y") -> 1 | F5: =IFERROR(AVERAGEIFS(Tracker!$P$4:$P$153,Tracker!$B$4:$B$153,A5),0) -> 3.5
A6: Two Pointers | B6: =COUNTIF(Tracker!$B$4:$B$153,A6) -> 5 | C6: =COUNTIFS(Tracker!$B$4:$B$153,A6,Tracker!$Q$4:$Q$153,"Solved Independently")+COUNTIFS(Tracker!$B$4:$B$153,A6,Tracker!$Q$4:$Q$153,"Mastered") -> 0 | D6: =IFERROR(C6/B6,0) -> 0 | E6: =COUNTIFS(Tracker!$B$4:$B$153,A6,Tracker!$M$4:$M$153,"Y") -> 0 | F6: =IFERROR(AVERAGEIFS(Tracker!$P$4:$P$153,Tracker!$B$4:$B$153,A6),0) -> 0
A7: Sliding Window | B7: =COUNTIF(Tracker!$B$4:$B$153,A7) -> 6 | C7: =COUNTIFS(Tracker!$B$4:$B$153,A7,Tracker!$Q$4:$Q$153,"Solved Independently")+COUNTIFS(Tracker!$B$4:$B$153,A7,Tracker!$Q$4:$Q$153,"Mastered") -> 0 | D7: =IFERROR(C7/B7,0) -> 0 | E7: =COUNTIFS(Tracker!$B$4:$B$153,A7,Tracker!$M$4:$M$153,"Y") -> 0 | F7: =IFERROR(AVERAGEIFS(Tracker!$P$4:$P$153,Tracker!$B$4:$B$153,A7),0) -> 0
A8: Stack | B8: =COUNTIF(Tracker!$B$4:$B$153,A8) -> 6 | C8: =COUNTIFS(Tracker!$B$4:$B$153,A8,Tracker!$Q$4:$Q$153,"Solved Independently")+COUNTIFS(Tracker!$B$4:$B$153,A8,Tracker!$Q$4:$Q$153,"Mastered") -> 0 | D8: =IFERROR(C8/B8,0) -> 0 | E8: =COUNTIFS(Tracker!$B$4:$B$153,A8,Tracker!$M$4:$M$153,"Y") -> 1 | F8: =IFERROR(AVERAGEIFS(Tracker!$P$4:$P$153,Tracker!$B$4:$B$153,A8),0) -> 2
A9: Binary Search | B9: =COUNTIF(Tracker!$B$4:$B$153,A9) -> 7 | C9: 0 | D9: =IFERROR(C9/B9,0) -> 0 | E9: =COUNTIFS(Tracker!$B$4:$B$153,A9,Tracker!$M$4:$M$153,"Y") -> 1 | F9: =IFERROR(AVERAGEIFS(Tracker!$P$4:$P$153,Tracker!$B$4:$B$153,A9),0) -> 2
A10: Linked List | B10: =COUNTIF(Tracker!$B$4:$B$153,A10) -> 11 | C10: 0 | D10: =IFERROR(C10/B10,0) -> 0 | E10: =COUNTIFS(Tracker!$B$4:$B$153,A10,Tracker!$M$4:$M$153,"Y") -> 3 | F10: =IFERROR(AVERAGEIFS(Tracker!$P$4:$P$153,Tracker!$B$4:$B$153,A10),0) -> 2
A11: Trees | B11: =COUNTIF(Tracker!$B$4:$B$153,A11) -> 15 | C11: =COUNTIFS(Tracker!$B$4:$B$153,A11,Tracker!$Q$4:$Q$153,"Solved Independently")+COUNTIFS(Tracker!$B$4:$B$153,A11,Tracker!$Q$4:$Q$153,"Mastered") -> 0 | D11: =IFERROR(C11/B11,0) -> 0 | E11: =COUNTIFS(Tracker!$B$4:$B$153,A11,Tracker!$M$4:$M$153,"Y") -> 0 | F11: =IFERROR(AVERAGEIFS(Tracker!$P$4:$P$153,Tracker!$B$4:$B$153,A11),0) -> 0
A12: Heap / Priority Queue | B12: =COUNTIF(Tracker!$B$4:$B$153,A12) -> 7 | C12: =COUNTIFS(Tracker!$B$4:$B$153,A12,Tracker!$Q$4:$Q$153,"Solved Independently")+COUNTIFS(Tracker!$B$4:$B$153,A12,Tracker!$Q$4:$Q$153,"Mastered") -> 0 | D12: =IFERROR(C12/B12,0) -> 0 | E12: =COUNTIFS(Tracker!$B$4:$B$153,A12,Tracker!$M$4:$M$153,"Y") -> 0 | F12: =IFERROR(AVERAGEIFS(Tracker!$P$4:$P$153,Tracker!$B$4:$B$153,A12),0) -> 0
A13: Backtracking | B13: =COUNTIF(Tracker!$B$4:$B$153,A13) -> 10 | C13: =COUNTIFS(Tracker!$B$4:$B$153,A13,Tracker!$Q$4:$Q$153,"Solved Independently")+COUNTIFS(Tracker!$B$4:$B$153,A13,Tracker!$Q$4:$Q$153,"Mastered") -> 0 | D13: =IFERROR(C13/B13,0) -> 0 | E13: =COUNTIFS(Tracker!$B$4:$B$153,A13,Tracker!$M$4:$M$153,"Y") -> 0 | F13: =IFERROR(AVERAGEIFS(Tracker!$P$4:$P$153,Tracker!$B$4:$B$153,A13),0) -> 0
A14: Tries | B14: =COUNTIF(Tracker!$B$4:$B$153,A14) -> 3 | C14: =COUNTIFS(Tracker!$B$4:$B$153,A14,Tracker!$Q$4:$Q$153,"Solved Independently")+COUNTIFS(Tracker!$B$4:$B$153,A14,Tracker!$Q$4:$Q$153,"Mastered") -> 0 | D14: =IFERROR(C14/B14,0) -> 0 | E14: =COUNTIFS(Tracker!$B$4:$B$153,A14,Tracker!$M$4:$M$153,"Y") -> 0 | F14: =IFERROR(AVERAGEIFS(Tracker!$P$4:$P$153,Tracker!$B$4:$B$153,A14),0) -> 0
A15: Graphs | B15: =COUNTIF(Tracker!$B$4:$B$153,A15) -> 13 | C15: =COUNTIFS(Tracker!$B$4:$B$153,A15,Tracker!$Q$4:$Q$153,"Solved Independently")+COUNTIFS(Tracker!$B$4:$B$153,A15,Tracker!$Q$4:$Q$153,"Mastered") -> 0 | D15: =IFERROR(C15/B15,0) -> 0 | E15: =COUNTIFS(Tracker!$B$4:$B$153,A15,Tracker!$M$4:$M$153,"Y") -> 0 | F15: =IFERROR(AVERAGEIFS(Tracker!$P$4:$P$153,Tracker!$B$4:$B$153,A15),0) -> 0
A16: Advanced Graphs | B16: =COUNTIF(Tracker!$B$4:$B$153,A16) -> 6 | C16: =COUNTIFS(Tracker!$B$4:$B$153,A16,Tracker!$Q$4:$Q$153,"Solved Independently")+COUNTIFS(Tracker!$B$4:$B$153,A16,Tracker!$Q$4:$Q$153,"Mastered") -> 0 | D16: =IFERROR(C16/B16,0) -> 0 | E16: =COUNTIFS(Tracker!$B$4:$B$153,A16,Tracker!$M$4:$M$153,"Y") -> 0 | F16: =IFERROR(AVERAGEIFS(Tracker!$P$4:$P$153,Tracker!$B$4:$B$153,A16),0) -> 0
A17: 1-D Dynamic Programming | B17: =COUNTIF(Tracker!$B$4:$B$153,A17) -> 12 | C17: =COUNTIFS(Tracker!$B$4:$B$153,A17,Tracker!$Q$4:$Q$153,"Solved Independently")+COUNTIFS(Tracker!$B$4:$B$153,A17,Tracker!$Q$4:$Q$153,"Mastered") -> 0 | D17: =IFERROR(C17/B17,0) -> 0 | E17: =COUNTIFS(Tracker!$B$4:$B$153,A17,Tracker!$M$4:$M$153,"Y") -> 0 | F17: =IFERROR(AVERAGEIFS(Tracker!$P$4:$P$153,Tracker!$B$4:$B$153,A17),0) -> 0
A18: 2-D Dynamic Programming | B18: =COUNTIF(Tracker!$B$4:$B$153,A18) -> 11 | C18: =COUNTIFS(Tracker!$B$4:$B$153,A18,Tracker!$Q$4:$Q$153,"Solved Independently")+COUNTIFS(Tracker!$B$4:$B$153,A18,Tracker!$Q$4:$Q$153,"Mastered") -> 0 | D18: =IFERROR(C18/B18,0) -> 0 | E18: =COUNTIFS(Tracker!$B$4:$B$153,A18,Tracker!$M$4:$M$153,"Y") -> 0 | F18: =IFERROR(AVERAGEIFS(Tracker!$P$4:$P$153,Tracker!$B$4:$B$153,A18),0) -> 0
A19: Greedy | B19: =COUNTIF(Tracker!$B$4:$B$153,A19) -> 8 | C19: =COUNTIFS(Tracker!$B$4:$B$153,A19,Tracker!$Q$4:$Q$153,"Solved Independently")+COUNTIFS(Tracker!$B$4:$B$153,A19,Tracker!$Q$4:$Q$153,"Mastered") -> 0 | D19: =IFERROR(C19/B19,0) -> 0 | E19: =COUNTIFS(Tracker!$B$4:$B$153,A19,Tracker!$M$4:$M$153,"Y") -> 0 | F19: =IFERROR(AVERAGEIFS(Tracker!$P$4:$P$153,Tracker!$B$4:$B$153,A19),0) -> 0
A20: Intervals | B20: =COUNTIF(Tracker!$B$4:$B$153,A20) -> 6 | C20: =COUNTIFS(Tracker!$B$4:$B$153,A20,Tracker!$Q$4:$Q$153,"Solved Independently")+COUNTIFS(Tracker!$B$4:$B$153,A20,Tracker!$Q$4:$Q$153,"Mastered") -> 0 | D20: =IFERROR(C20/B20,0) -> 0 | E20: =COUNTIFS(Tracker!$B$4:$B$153,A20,Tracker!$M$4:$M$153,"Y") -> 0 | F20: =IFERROR(AVERAGEIFS(Tracker!$P$4:$P$153,Tracker!$B$4:$B$153,A20),0) -> 0
A21: Math & Geometry | B21: =COUNTIF(Tracker!$B$4:$B$153,A21) -> 8 | C21: =COUNTIFS(Tracker!$B$4:$B$153,A21,Tracker!$Q$4:$Q$153,"Solved Independently")+COUNTIFS(Tracker!$B$4:$B$153,A21,Tracker!$Q$4:$Q$153,"Mastered") -> 0 | D21: =IFERROR(C21/B21,0) -> 0 | E21: =COUNTIFS(Tracker!$B$4:$B$153,A21,Tracker!$M$4:$M$153,"Y") -> 0 | F21: =IFERROR(AVERAGEIFS(Tracker!$P$4:$P$153,Tracker!$B$4:$B$153,A21),0) -> 0
A22: Bit Manipulation | B22: =COUNTIF(Tracker!$B$4:$B$153,A22) -> 7 | C22: =COUNTIFS(Tracker!$B$4:$B$153,A22,Tracker!$Q$4:$Q$153,"Solved Independently")+COUNTIFS(Tracker!$B$4:$B$153,A22,Tracker!$Q$4:$Q$153,"Mastered") -> 0 | D22: =IFERROR(C22/B22,0) -> 0 | E22: =COUNTIFS(Tracker!$B$4:$B$153,A22,Tracker!$M$4:$M$153,"Y") -> 0 | F22: =IFERROR(AVERAGEIFS(Tracker!$P$4:$P$153,Tracker!$B$4:$B$153,A22),0) -> 0
A23: TOTAL | B23: =SUM(B5:B22) -> 150 | C23: =SUM(C5:C22) -> 1 | D23: =IFERROR(C23/B23,0) -> 0.0066666667 | E23: =SUM(E5:E22) -> 6 | F23: =IFERROR(AVERAGE(F5:F22),0) -> 0.52777778

Sheet Method & Timeline
A1: NeetCode's Method + Your Realistic Timeline
A3: 1. NeetCode's Own Method (from his official prep guide, matching the video's philosophy)
B5: 1. Just start. Don't overthink the plan — open the list in topic order and solve problem #1. The problems are sequenced so each one builds on the last; solving in order matters more than picking and choosing.
B6: 2. Always attempt a problem yourself first. Try drawing it out on paper before writing any code.
B7: 3. Don't sit stuck for hours. If you're not making progress after roughly 15-20 minutes, look at the solution — that's normal, not cheating.
B8: 4. Never copy-paste a solution without understanding it, and never blindly memorize an algorithm. The goal is understanding why it works, not reproducing it from memory.
B9: 5. If even the solution takes you 45-60 minutes to understand, that's a signal to step back and try an easier problem first before returning to this one.
B10: 6. Revisit problems that gave you trouble — resolve them completely from scratch later, without looking. This is what actually builds pattern recognition, not just recognition of a solution you've already seen.
B11: 7. Interview-readiness benchmark: you're in good shape once you can solve most medium problems you haven't seen before in about 20-25 minutes.
B12: 8. If time is tight, prioritize Arrays, Hash Maps, Trees, and Graphs first — these are the highest-leverage, most frequently recurring topics in real interviews.
B13: 9. Difficulty labels aren't always accurate — some 'Medium' problems are harder than some 'Hard' ones. Don't fixate on the label; focus on learning the underlying algorithm.
A15: 2. My Input — How to Use This Sheet to Actually Follow That Method
B17: • The tracker isn't just a checklist — the columns exist specifically to enforce NeetCode's method. 'Solved Independently?' and 'Watched Video?' together tell you honestly whether you actually solved it or recognized a solution you'd seen — be strict with yourself here, this is the single most gamed column on any tracker.
B18: • Use 'Needs Revisit?' liberally in your first pass — mark Y for anything you needed the video for, anything that took over 20 minutes, or anything that felt shaky even after solving it. Don't be optimistic here; a false 'N' is the thing that quietly kills retention.
B19: • The 'Confidence (1-5)' score is for YOU three weeks from now, not for today. A '5' should mean 'I could solve a variant of this cold, in an interview, under a stranger's eyes' — not 'I understood the solution when I read it.'
B20: • Given you're coming from 10 years of DS/ML engineering, not fresh out of a CS degree — your comparative advantage is in the array/DP/graph problems that map to real engineering intuition, and your gap is likely to be in the more 'puzzle-shaped' topics (Backtracking, Bit Manipulation, some Greedy problems) that don't show up in day-to-day ML engineering work. Expect those sections to take longer per problem than the Arrays/Trees/Graphs sections — budget for that instead of being surprised by it.
B21: • Two problems a day is a genuinely sustainable pace for someone working full-time — but only if you also protect a short daily slot for revisits (see Phase 2 below). Two NEW problems with zero revisiting is the single most common way people finish all 150 and then fail their first real interview anyway, because they solved each problem once and never again.
B22: • The list is already sequenced so Dynamic Programming comes after Graphs — resist the urge to jump ahead to DP out of curiosity. The pattern only really clicks once recursion and backtracking are already comfortable.
A24: 3. Realistic Timeline at 2 New Problems / Day
B26: Set your real start date below (blue cell) — every date in the table recalculates automatically. Phase 1 durations are computed directly from the problem counts on the Tracker tab.
B28: Your Start Date: | C28: 2026-08-10
B30: Topic | C30: # Problems | D30: Days Needed (@2/day) | E30: Start Date | F30: End Date
B31: Arrays & Hashing | C31: =COUNTIF(Tracker!$B$4:$B$153,B31) -> 9 | D31: =ROUNDUP(C31/2,0) -> 5 | E31: =C28 -> 2026-08-10 | F31: =E31+D31-1 -> 46248
B32: Two Pointers | C32: =COUNTIF(Tracker!$B$4:$B$153,B32) -> 5 | D32: =ROUNDUP(C32/2,0) -> 3 | E32: =F31+1 -> 46249 | F32: =E32+D32-1 -> 46251
B33: Sliding Window | C33: =COUNTIF(Tracker!$B$4:$B$153,B33) -> 6 | D33: =ROUNDUP(C33/2,0) -> 3 | E33: =F32+1 -> 46252 | F33: =E33+D33-1 -> 46254
B34: Stack | C34: =COUNTIF(Tracker!$B$4:$B$153,B34) -> 6 | D34: =ROUNDUP(C34/2,0) -> 3 | E34: =F33+1 -> 46255 | F34: =E34+D34-1 -> 46257
B35: Binary Search | C35: =COUNTIF(Tracker!$B$4:$B$153,B35) -> 7 | D35: =ROUNDUP(C35/2,0) -> 4 | E35: =F34+1 -> 46258 | F35: =E35+D35-1 -> 46261
B36: Linked List | C36: =COUNTIF(Tracker!$B$4:$B$153,B36) -> 11 | D36: =ROUNDUP(C36/2,0) -> 6 | E36: =F35+1 -> 46262 | F36: =E36+D36-1 -> 46267
B37: Trees | C37: =COUNTIF(Tracker!$B$4:$B$153,B37) -> 15 | D37: =ROUNDUP(C37/2,0) -> 8 | E37: =F36+1 -> 46268 | F37: =E37+D37-1 -> 46275
B38: Heap / Priority Queue | C38: =COUNTIF(Tracker!$B$4:$B$153,B38) -> 7 | D38: =ROUNDUP(C38/2,0) -> 4 | E38: =F37+1 -> 46276 | F38: =E38+D38-1 -> 46279
B39: Backtracking | C39: =COUNTIF(Tracker!$B$4:$B$153,B39) -> 10 | D39: =ROUNDUP(C39/2,0) -> 5 | E39: =F38+1 -> 46280 | F39: =E39+D39-1 -> 46284
B40: Tries | C40: =COUNTIF(Tracker!$B$4:$B$153,B40) -> 3 | D40: =ROUNDUP(C40/2,0) -> 2 | E40: =F39+1 -> 46285 | F40: =E40+D40-1 -> 46286
B41: Graphs | C41: =COUNTIF(Tracker!$B$4:$B$153,B41) -> 13 | D41: =ROUNDUP(C41/2,0) -> 7 | E41: =F40+1 -> 46287 | F41: =E41+D41-1 -> 46293
B42: Advanced Graphs | C42: =COUNTIF(Tracker!$B$4:$B$153,B42) -> 6 | D42: =ROUNDUP(C42/2,0) -> 3 | E42: =F41+1 -> 46294 | F42: =E42+D42-1 -> 46296
B43: 1-D Dynamic Programming | C43: =COUNTIF(Tracker!$B$4:$B$153,B43) -> 12 | D43: =ROUNDUP(C43/2,0) -> 6 | E43: =F42+1 -> 46297 | F43: =E43+D43-1 -> 46302
... B48: Bit Manipulation | C48: =COUNTIF(Tracker!$B$4:$B$153,B48) -> 7 | D48: =ROUNDUP(C48/2,0) -> 4 | E48: =F47+1 -> 46320 | F48: =E48+D48-1 -> 46323
B49: Phase 1 Total (first full pass, all 150 problems) | C49: =SUM(C31:C48) -> 150 | D49: =SUM(D31:D48) -> 80 | E49: =C28 -> 2026-08-10 | F49: =F48 -> 46323
B51: Phase 2 & 3 durations below are my estimate, not derived from the Tracker — based on typical revisit-volume reports from people who've completed NeetCode 150 (roughly 35-45% of problems get flagged 'needs revisit' on a first pass).
B53: Phase | C53: What You're Doing | D53: Estimated Duration (days) | E53: Start Date | F53: End Date
B54: Phase 2 — Spaced Repetition Pass | C54: Re-solve every problem flagged 'Needs Revisit' from scratch, no notes. ~20-30 min/day alongside new Phase-1 problems, running in parallel from week 2 onward — this row shows the tail end after Phase 1 finishes. | D54: 21 | E54: =F49+1 -> 46324 | F54: =E54+D54-1 -> 46344
...
